<?xml version="1.0" ?>
<!-- =================================================================================== -->
<!-- |    This document was autogenerated by xacro from mini_hex.xacro                 | -->
<!-- |    EDITING THIS FILE BY HAND IS NOT RECOMMENDED                                 | -->
<!-- =================================================================================== -->
<robot name="mini_hex">
  <mujoco>
    <compiler balanceinertia="true" discardvisual="false" meshdir="../meshes/"/>
  </mujoco>
  <link name="world">
</link>
  <link name="link_trunk">
    <inertial>
      <origin rpy="0 0 0" xyz="0.016 0.0 -0.0001"/>
      <mass value="11.6964"/>
      <inertia ixx="61653481E-09" ixy="39455E-09" ixz="10933035E-09" iyy="455441612E-09" iyz="-2962E-09" izz="485718923E-09"/>
    </inertial>
    <visual>
      <origin rpy="-1.57 0 0" xyz="0 0 0"/>
      <geometry>
        <mesh filename="../meshes/trunk.STL"/>
      </geometry>
      <material name="">
        <color rgba="0.79216 0.81961 0.93333 1"/>
      </material>
    </visual>
    <collision>
      <origin rpy="0 0 0" xyz="0 0 0"/>
      <geometry>
        <box size="0.58 0.16 0.1"/>
      </geometry>
      <material>
        <color rgba="1.0 0.0 0.0 0.5"/>
      </material>
    </collision>
  </link>
  <joint name="joint_fixed_world" type="floating">
    <origin rpy="0 0 0" xyz="0 0 0"/>
    <parent link="world"/>
    <child link="link_trunk"/>
  </joint>

  <link name="link_front_left_hip">
    <inertial>
      <origin rpy="0 0 0" xyz="-0.0023 -0.0032 0.003"/>
      <mass value="0.5251"/>
      <inertia ixx="398945E-09" ixy="-1.2165e-05" ixz="1.54e-07" iyy="394485E-09" iyz="-3.329e-06" izz="421979E-09"/>
    </inertial>
    <visual>
      <origin rpy="-1.57 0 0" xyz="0 0 0"/>
      <geometry>
        <mesh filename="../meshes/hip.STL"/>
      </geometry>
      <material name="">
        <color rgba="0.752941176470588 0.752941176470588 0.752941176470588 1"/>
      </material>
    </visual>
    <collision>
      <origin rpy="-1.57 0 0" xyz="0 0 0"/>
      <geometry>
        <cylinder length="0.03" radius="0.02"/>
      </geometry>
    </collision>
  </link>
  <joint name="joint_front_left_abad" type="revolute">
    <origin rpy="0 0 0" xyz="0.3508 0.05 0"/>
    <parent link="link_trunk"/>
    <child link="link_front_left_hip"/>
    <axis xyz="1 0 0"/>
    <limit effort="45" lower="-2.9845105" upper="2.9845105" velocity="30"/>
  </joint>

  <link name="link_front_left_thigh">
    <inertial>
      <origin rpy="0 0 0" xyz="-0.0041 -0.0258 -0.0303"/>
      <mass value="0.9013"/>
      <inertia ixx="5044532E-09" ixy="-8.2142e-05" ixz="0.000380263" iyy="4863783E-09" iyz="-0.00070022" izz="1073858E-09"/>
    </inertial>
    <visual>
      <origin rpy="-1.57 0 0" xyz="0 0 0"/>
      <geometry>
        <mesh filename="../meshes/thigh_left.STL"/>
      </geometry>
      <material name="">
        <color rgba="0.752941176470588 0.752941176470588 0.752941176470588 1"/>
      </material>
    </visual>
    <collision>
      <origin rpy="0 0 0" xyz="-0.02 0 -0.1"/>
      <geometry>
        <box size="0.04 0.02 0.3"/>
      </geometry>
    </collision>
  </link>
  <joint name="joint_front_left_thigh_pitch" type="revolute">
    <origin rpy="0 0 0" xyz="0.0  0.1058 0.0"/>
    <parent link="link_front_left_hip"/>
    <child link="link_front_left_thigh"/>
    <axis xyz="0 1 0"/>
    <limit effort="45" lower="-3.14" upper="3.14" velocity="30"/>
  </joint>

  <link name="link_front_left_calf">
    <inertial>
      <origin rpy="0 0 0" xyz="0.0028 0.0 -0.1278"/>
      <mass value="0.1353"/>
      <inertia ixx="1133339E-09" ixy="1e-09" ixz="-4.9201e-05" iyy="1157176E-09" iyz="-1e-08" izz="35874E-09"/>
    </inertial>
    <visual>
      <origin rpy="-1.57 0 0" xyz="0 0 0"/>
      <geometry>
        <mesh filename="../meshes/calf.STL"/>
      </geometry>
      <material name="">
        <color rgba="0.752941176470588 0.752941176470588 0.752941176470588 1"/>
      </material>
    </visual>
    <collision>
      <origin rpy="0 0 0" xyz="0 0 -0.138"/>
      <geometry>
        <box size="0.02 0.02 0.155"/>
      </geometry>
    </collision>
  </link>
  <joint name="joint_front_left_calf_pitch" type="revolute">
    <origin rpy="0 0 0" xyz="0.0 0.0 -0.23"/>
    <parent link="link_front_left_thigh"/>
    <child link="link_front_left_calf"/>
    <axis xyz="0 1 0"/>
    <limit effort="45" lower="-3.14" upper="3.14" velocity="30"/>
  </joint>

  <link name="link_front_left_foot">
    <inertial>
      <origin xyz="0 0 0" rpy="0 0 0" />
      <mass value="0.04" />
      <inertia ixx="9.6e-06" ixy="0" ixz="0" iyy="9.6e-06" iyz="0" izz="9.6e-06" />
    </inertial>
    <visual>
      <origin xyz="0 0 0" rpy="0 0 0" />
      <geometry>
        <sphere radius="0.02"/>
      </geometry>
    </visual>
    <collision>
      <origin rpy="0 0 0" xyz="0 0 0" />
      <geometry>
        <sphere radius="0.02" />
      </geometry>
    </collision>
  </link>
  <joint name="front_left_foot_joint" type="fixed" dont_collapse="true">
    <origin xyz="0 0 -0.23" rpy="0 0 0" />
    <parent link="link_front_left_calf" />
    <child link="link_front_left_foot" />
    <axis xyz="0 0 0" />
  </joint>


  <link name="link_front_right_hip">
    <inertial>
      <origin rpy="0 0 0" xyz="-0.0023 0.0032 0.003"/>
      <mass value="0.5251"/>
      <inertia ixx="398945E-09" ixy="1.2165e-05" ixz="1.54e-07" iyy="394485E-09" iyz="3.329e-06" izz="421979E-09"/>
    </inertial>
    <visual>
      <origin rpy="3.141592653589793 0 0" xyz="0 0 0"/>
      <geometry>
        <mesh filename="../meshes/hip.STL"/>
      </geometry>
      <material name="">
        <color rgba="0.752941176470588 0.752941176470588 0.752941176470588 1"/>
      </material>
    </visual>
    <collision>
      <origin rpy="-1.57 0 0" xyz="0 0 0"/>
      <geometry>
        <cylinder length="0.03" radius="0.02"/>
      </geometry>
    </collision>
  </link>
  <joint name="joint_front_right_abad" type="revolute">
    <origin rpy="0 0 0" xyz="0.3508 -0.05 0"/>
    <parent link="link_trunk"/>
    <child link="link_front_right_hip"/>
    <axis xyz="1 0 0"/>
    <limit effort="45" lower="-2.9845105" upper="2.9845105" velocity="30"/>
  </joint>

  <link name="link_front_right_thigh">
    <inertial>
      <origin rpy="0 0 0" xyz="-0.0041 0.0258 -0.0303"/>
      <mass value="0.9013"/>
      <inertia ixx="5044532E-09" ixy="8.2142e-05" ixz="0.000380263" iyy="4863783E-09" iyz="0.00070022" izz="1073858E-09"/>
    </inertial>
    <visual>
      <origin rpy="-1.57 0 0" xyz="0 0 0"/>
      <geometry>
        <mesh filename="../meshes/thigh_right.STL"/>
      </geometry>
      <material name="">
        <color rgba="0.752941176470588 0.752941176470588 0.752941176470588 1"/>
      </material>
    </visual>
    <collision>
      <origin rpy="0 0 0" xyz="-0.02 0 -0.1"/>
      <geometry>
        <box size="0.04 0.02 0.3"/>
      </geometry>
    </collision>
  </link>
  <joint name="joint_front_right_thigh_pitch" type="revolute">
    <origin rpy="0 0 0" xyz="0.0  -0.1058 0.0"/>
    <parent link="link_front_right_hip"/>
    <child link="link_front_right_thigh"/>
    <axis xyz="0 1 0"/>
    <limit effort="45" lower="-3.14" upper="3.14" velocity="30"/>
  </joint>

  <link name="link_front_right_calf">
    <inertial>
      <origin rpy="0 0 0" xyz="0.0028 -0.0 -0.1278"/>
      <mass value="0.1353"/>
      <inertia ixx="1133339E-09" ixy="-1e-09" ixz="-4.9201e-05" iyy="1157176E-09" iyz="1e-08" izz="35874E-09"/>
    </inertial>
    <visual>
      <origin rpy="-1.57 0 0" xyz="0 0 0"/>
      <geometry>
        <mesh filename="../meshes/calf.STL"/>
      </geometry>
      <material name="">
        <color rgba="0.752941176470588 0.752941176470588 0.752941176470588 1"/>
      </material>
    </visual>
    <collision>
      <origin rpy="0 0 0" xyz="0 0 -0.138"/>
      <geometry>
        <box size="0.02 0.02 0.155"/>
      </geometry>
    </collision>
  </link>
  <joint name="joint_front_right_calf_pitch" type="revolute">
    <origin rpy="0 0 0" xyz="0.0 0.0 -0.23"/>
    <parent link="link_front_right_thigh"/>
    <child link="link_front_right_calf"/>
    <axis xyz="0 1 0"/>
    <limit effort="45" lower="-3.14" upper="3.14" velocity="30"/>
  </joint>

  <link name="link_front_right_foot">
    <inertial>
      <origin xyz="0 0 0" rpy="0 0 0" />
      <mass value="0.04" />
      <inertia ixx="9.6e-06" ixy="0" ixz="0" iyy="9.6e-06" iyz="0" izz="9.6e-06" />
    </inertial>
    <visual>
      <origin xyz="0 0 0" rpy="0 0 0" />
      <geometry>
        <sphere radius="0.02"/>
      </geometry>
    </visual>
    <collision>
      <origin rpy="0 0 0" xyz="0 0 0" />
      <geometry>
        <sphere radius="0.02" />
      </geometry>
    </collision>
  </link>
  <joint name="front_right_foot_joint" type="fixed" dont_collapse="true">
    <origin xyz="0 0 -0.23" rpy="0 0 0" />
    <parent link="link_front_right_calf" />
    <child link="link_front_right_foot" />
    <axis xyz="0 0 0" />
  </joint>

  <link name="link_mid_left_hip">
    <inertial>
      <origin rpy="0 0 0" xyz="-0.0023 -0.0032 0.003"/>
      <mass value="0.5251"/>
      <inertia ixx="398945E-09" ixy="-1.2165e-05" ixz="1.54e-07" iyy="394485E-09" iyz="-3.329e-06" izz="421979E-09"/>
    </inertial>
    <visual>
      <origin rpy="-1.57 0 0" xyz="0 0 0"/>
      <geometry>
        <mesh filename="../meshes/hip.STL"/>
      </geometry>
      <material name="">
        <color rgba="0.752941176470588 0.752941176470588 0.752941176470588 1"/>
      </material>
    </visual>
    <collision>
      <origin rpy="-1.57 0 0" xyz="0 0.04 0"/>
      <geometry>
        <cylinder length="0.03" radius="0.02"/>
      </geometry>
    </collision>
  </link>
  <joint name="joint_mid_left_abad" type="revolute">
    <origin rpy="0 0 0" xyz="0.0 0.1275 0"/>
    <parent link="link_trunk"/>
    <child link="link_mid_left_hip"/>
    <axis xyz="1 0 0"/>
    <limit effort="45" lower="-2.9845105" upper="2.9845105" velocity="30"/>
  </joint>

  <link name="link_mid_left_thigh">
    <inertial>
      <origin rpy="0 0 0" xyz="-0.0041 -0.0258 -0.0303"/>
      <mass value="0.9013"/>
      <inertia ixx="5044532E-09" ixy="-8.2142e-05" ixz="0.000380263" iyy="4863783E-09" iyz="-0.00070022" izz="1073858E-09"/>
    </inertial>
    <visual>
      <origin rpy="-1.57 0 0" xyz="0 0 0"/>
      <geometry>
        <mesh filename="../meshes/thigh_left.STL"/>
      </geometry>
      <material name="">
        <color rgba="0.752941176470588 0.752941176470588 0.752941176470588 1"/>
      </material>
    </visual>
    <collision>
      <origin rpy="0 0 0" xyz="-0.02 0 -0.1"/>
      <geometry>
        <box size="0.04 0.02 0.3"/>
      </geometry>
    </collision>
  </link>
  <joint name="joint_mid_left_thigh_pitch" type="revolute">
    <origin rpy="0 0 0" xyz="0.0  0.1058 0.0"/>
    <parent link="link_mid_left_hip"/>
    <child link="link_mid_left_thigh"/>
    <axis xyz="0 1 0"/>
    <limit effort="45" lower="-3.14" upper="3.14" velocity="30"/>
  </joint>

  <link name="link_mid_left_calf">
    <inertial>
      <origin rpy="0 0 0" xyz="0.0028 0.0 -0.1278"/>
      <mass value="0.1353"/>
      <inertia ixx="1133339E-09" ixy="1e-09" ixz="-4.9201e-05" iyy="1157176E-09" iyz="-1e-08" izz="35874E-09"/>
    </inertial>
    <visual>
      <origin rpy="-1.57 0 0" xyz="0 0 0"/>
      <geometry>
        <mesh filename="../meshes/calf.STL"/>
      </geometry>
      <material name="">
        <color rgba="0.752941176470588 0.752941176470588 0.752941176470588 1"/>
      </material>
    </visual>
    <collision>
      <origin rpy="0 0 0" xyz="0 0 -0.138"/>
      <geometry>
        <box size="0.02 0.02 0.155"/>
      </geometry>
    </collision>
  </link>
  <joint name="joint_mid_left_calf_pitch" type="revolute">
    <origin rpy="0 0 0" xyz="0.0 0.0 -0.23"/>
    <parent link="link_mid_left_thigh"/>
    <child link="link_mid_left_calf"/>
    <axis xyz="0 1 0"/>
    <limit effort="45" lower="-3.14" upper="3.14" velocity="30"/>
  </joint>

  <link name="link_mid_left_foot">
    <inertial>
      <origin xyz="0 0 0" rpy="0 0 0" />
      <mass value="0.04" />
      <inertia ixx="9.6e-06" ixy="0" ixz="0" iyy="9.6e-06" iyz="0" izz="9.6e-06" />
    </inertial>
    <visual>
      <origin xyz="0 0 0" rpy="0 0 0" />
      <geometry>
        <sphere radius="0.02"/>
      </geometry>
    </visual>
    <collision>
      <origin rpy="0 0 0" xyz="0 0 0" />
      <geometry>
        <sphere radius="0.02" />
      </geometry>
    </collision>
  </link>
  <joint name="mid_left_foot_joint" type="fixed" dont_collapse="true">
    <origin xyz="0 0 -0.23" rpy="0 0 0" />
    <parent link="link_mid_left_calf" />
    <child link="link_mid_left_foot" />
    <axis xyz="0 0 0" />
  </joint>

  <link name="link_mid_right_hip">
    <inertial>
      <origin rpy="0 0 0" xyz="-0.0023 0.0032 0.003"/>
      <mass value="0.5251"/>
      <inertia ixx="398945E-09" ixy="1.2165e-05" ixz="1.54e-07" iyy="394485E-09" iyz="3.329e-06" izz="421979E-09"/>
    </inertial>
    <visual>
      <origin rpy="3.141592653589793 0 0" xyz="0 0 0"/>
      <geometry>
        <mesh filename="../meshes/hip.STL"/>
      </geometry>
      <material name="">
        <color rgba="0.752941176470588 0.752941176470588 0.752941176470588 1"/>
      </material>
    </visual>
    <collision>
      <origin rpy="-1.57 0 0" xyz="0 -0.04 0"/>
      <geometry>
        <cylinder length="0.03" radius="0.02"/>
      </geometry>
    </collision>
  </link>
  <joint name="joint_mid_right_abad" type="revolute">
    <origin rpy="0 0 0" xyz="0.0 -0.1275 0"/>
    <parent link="link_trunk"/>
    <child link="link_mid_right_hip"/>
    <axis xyz="1 0 0"/>
    <limit effort="45" lower="-2.9845105" upper="2.9845105" velocity="30"/>
  </joint>

  <link name="link_mid_right_thigh">
    <inertial>
      <origin rpy="0 0 0" xyz="-0.0041 0.0258 -0.0303"/>
      <mass value="0.9013"/>
      <inertia ixx="5044532E-09" ixy="8.2142e-05" ixz="0.000380263" iyy="4863783E-09" iyz="0.00070022" izz="1073858E-09"/>
    </inertial>
    <visual>
      <origin rpy="-1.57 0 0" xyz="0 0 0"/>
      <geometry>
        <mesh filename="../meshes/thigh_right.STL"/>
      </geometry>
      <material name="">
        <color rgba="0.752941176470588 0.752941176470588 0.752941176470588 1"/>
      </material>
    </visual>
    <collision>
      <origin rpy="0 0 0" xyz="-0.02 0 -0.1"/>
      <geometry>
        <box size="0.04 0.02 0.3"/>
      </geometry>
    </collision>
  </link>
  <joint name="joint_mid_right_thigh_pitch" type="revolute">
    <origin rpy="0 0 0" xyz="0.0  -0.1058 0.0"/>
    <parent link="link_mid_right_hip"/>
    <child link="link_mid_right_thigh"/>
    <axis xyz="0 1 0"/>
    <limit effort="45" lower="-3.14" upper="3.14" velocity="30"/>
  </joint>

  <link name="link_mid_right_calf">
    <inertial>
      <origin rpy="0 0 0" xyz="0.0028 -0.0 -0.1278"/>
      <mass value="0.1353"/>
      <inertia ixx="1133339E-09" ixy="-1e-09" ixz="-4.9201e-05" iyy="1157176E-09" iyz="1e-08" izz="35874E-09"/>
    </inertial>
    <visual>
      <origin rpy="-1.57 0 0" xyz="0 0 0"/>
      <geometry>
        <mesh filename="../meshes/calf.STL"/>
      </geometry>
      <material name="">
        <color rgba="0.752941176470588 0.752941176470588 0.752941176470588 1"/>
      </material>
    </visual>
    <collision>
      <origin rpy="0 0 0" xyz="0 0 -0.138"/>
      <geometry>
        <box size="0.02 0.02 0.155"/>
      </geometry>
    </collision>
  </link>
  <joint name="joint_mid_right_calf_pitch" type="revolute">
    <origin rpy="0 0 0" xyz="0.0 0.0 -0.23"/>
    <parent link="link_mid_right_thigh"/>
    <child link="link_mid_right_calf"/>
    <axis xyz="0 1 0"/>
    <limit effort="45" lower="-3.14" upper="3.14" velocity="30"/>
  </joint>

  <link name="link_mid_right_foot">
    <inertial>
      <origin xyz="0 0 0" rpy="0 0 0" />
      <mass value="0.04" />
      <inertia ixx="9.6e-06" ixy="0" ixz="0" iyy="9.6e-06" iyz="0" izz="9.6e-06" />
    </inertial>
    <visual>
      <origin xyz="0 0 0" rpy="0 0 0" />
      <geometry>
        <sphere radius="0.02"/>
      </geometry>
    </visual>
    <collision>
      <origin rpy="0 0 0" xyz="0 0 0" />
      <geometry>
        <sphere radius="0.02" />
      </geometry>
    </collision>
  </link>
  <joint name="mid_right_foot_joint" type="fixed" dont_collapse="true">
    <origin xyz="0 0 -0.23" rpy="0 0 0" />
    <parent link="link_mid_right_calf" />
    <child link="link_mid_right_foot" />
    <axis xyz="0 0 0" />
  </joint>

  <link name="link_rear_left_hip">
    <inertial>
      <origin rpy="0 0 0" xyz="0.0023 -0.0032 0.003"/>
      <mass value="0.5251"/>
      <inertia ixx="398945E-09" ixy="1.2165e-05" ixz="-1.54e-07" iyy="394485E-09" iyz="-3.329e-06" izz="421979E-09"/>
    </inertial>
    <visual>
      <origin rpy="0 3.141592653589793 0" xyz="0 0 0"/>
      <geometry>
        <mesh filename="../meshes/hip.STL"/>
      </geometry>
      <material name="">
        <color rgba="0.752941176470588 0.752941176470588 0.752941176470588 1"/>
      </material>
    </visual>
    <collision>
      <origin rpy="-1.57 0 0" xyz="0 0 0"/>
      <geometry>
        <cylinder length="0.03" radius="0.02"/>
      </geometry>
    </collision>
  </link>
  <joint name="joint_rear_left_abad" type="revolute">
    <origin rpy="0 0 0" xyz="-0.3508 0.05 0"/>
    <parent link="link_trunk"/>
    <child link="link_rear_left_hip"/>
    <axis xyz="1 0 0"/>
    <limit effort="45" lower="-2.9845105" upper="2.9845105" velocity="30"/>
  </joint>

  <link name="link_rear_left_thigh">
    <inertial>
      <origin rpy="0 0 0" xyz="0.0041 -0.0258 -0.0303"/>
      <mass value="0.9013"/>
      <inertia ixx="5044532E-09" ixy="8.2142e-05" ixz="-0.000380263" iyy="4863783E-09" iyz="-0.00070022" izz="1073858E-09"/>
    </inertial>
    <visual>
      <origin rpy="-1.57 0 0" xyz="0 0 0"/>
      <geometry>
        <mesh filename="../meshes/thigh_left.STL"/>
      </geometry>
      <material name="">
        <color rgba="0.752941176470588 0.752941176470588 0.752941176470588 1"/>
      </material>
    </visual>
    <collision>
      <origin rpy="0 0 0" xyz="-0.02 0 -0.1"/>
      <geometry>
        <box size="0.04 0.02 0.3"/>
      </geometry>
    </collision>
  </link>
  <joint name="joint_rear_left_thigh_pitch" type="revolute">
    <origin rpy="0 0 0" xyz="-0.0  0.1058 0.0"/>
    <parent link="link_rear_left_hip"/>
    <child link="link_rear_left_thigh"/>
    <axis xyz="0 1 0"/>
    <limit effort="45" lower="-3.14" upper="3.14" velocity="30"/>
  </joint>

  <link name="link_rear_left_calf">
    <inertial>
      <origin rpy="0 0 0" xyz="-0.0028 0.0 -0.1278"/>
      <mass value="0.1353"/>
      <inertia ixx="1133339E-09" ixy="-1e-09" ixz="4.9201e-05" iyy="1157176E-09" iyz="-1e-08" izz="35874E-09"/>
    </inertial>
    <visual>
      <origin rpy="-1.57 0 0" xyz="0 0 0"/>
      <geometry>
        <mesh filename="../meshes/calf.STL"/>
      </geometry>
      <material name="">
        <color rgba="0.752941176470588 0.752941176470588 0.752941176470588 1"/>
      </material>
    </visual>
    <collision>
      <origin rpy="0 0 0" xyz="0 0 -0.138"/>
      <geometry>
        <box size="0.02 0.02 0.155"/>
      </geometry>
    </collision>
  </link>
  <joint name="joint_rear_left_calf_pitch" type="revolute">
    <origin rpy="0 0 0" xyz="0.0 0.0 -0.23"/>
    <parent link="link_rear_left_thigh"/>
    <child link="link_rear_left_calf"/>
    <axis xyz="0 1 0"/>
    <limit effort="45" lower="-3.14" upper="3.14" velocity="30"/>
  </joint>

  <link name="link_rear_left_foot">
    <inertial>
      <origin xyz="0 0 0" rpy="0 0 0" />
      <mass value="0.04" />
      <inertia ixx="9.6e-06" ixy="0" ixz="0" iyy="9.6e-06" iyz="0" izz="9.6e-06" />
    </inertial>
    <visual>
      <origin xyz="0 0 0" rpy="0 0 0" />
      <geometry>
        <sphere radius="0.02"/>
      </geometry>
    </visual>
    <collision>
      <origin rpy="0 0 0" xyz="0 0 0" />
      <geometry>
        <sphere radius="0.02" />
      </geometry>
    </collision>
  </link>
  <joint name="front_rear_left_joint" type="fixed" dont_collapse="true">
    <origin xyz="0 0 -0.23" rpy="0 0 0" />
    <parent link="link_rear_left_calf" />
    <child link="link_rear_left_foot" />
    <axis xyz="0 0 0" />
  </joint>

  <link name="link_rear_right_hip">
    <inertial>
      <origin rpy="0 0 0" xyz="0.0023 0.0032 0.003"/>
      <mass value="0.5251"/>
      <inertia ixx="398945E-09" ixy="-1.2165e-05" ixz="-1.54e-07" iyy="394485E-09" iyz="3.329e-06" izz="421979E-09"/>
    </inertial>
    <visual>
      <origin rpy="3.141592653589793 3.141592653589793 0" xyz="0 0 0"/>
      <geometry>
        <mesh filename="../meshes/hip.STL"/>
      </geometry>
      <material name="">
        <color rgba="0.752941176470588 0.752941176470588 0.752941176470588 1"/>
      </material>
    </visual>
    <collision>
      <origin rpy="-1.57 0 0" xyz="0 0 0"/>
      <geometry>
        <cylinder length="0.03" radius="0.02"/>
      </geometry>
    </collision>
  </link>
  <joint name="joint_rear_right_abad" type="revolute">
    <origin rpy="0 0 0" xyz="-0.3508 -0.05 0"/>
    <parent link="link_trunk"/>
    <child link="link_rear_right_hip"/>
    <axis xyz="1 0 0"/>
    <limit effort="45" lower="-2.9845105" upper="2.9845105" velocity="30"/>
  </joint>

  <link name="link_rear_right_thigh">
    <inertial>
      <origin rpy="0 0 0" xyz="0.0041 0.0258 -0.0303"/>
      <mass value="0.9013"/>
      <inertia ixx="5044532E-09" ixy="-8.2142e-05" ixz="-0.000380263" iyy="4863783E-09" iyz="0.00070022" izz="1073858E-09"/>
    </inertial>
    <visual>
      <origin rpy="-1.57 0 0" xyz="0 0 0"/>
      <geometry>
        <mesh filename="../meshes/thigh_right.STL"/>
      </geometry>
      <material name="">
        <color rgba="0.752941176470588 0.752941176470588 0.752941176470588 1"/>
      </material>
    </visual>
    <collision>
      <origin rpy="0 0 0" xyz="-0.02 0 -0.1"/>
      <geometry>
        <box size="0.04 0.02 0.3"/>
      </geometry>
    </collision>
  </link>
  <joint name="joint_rear_right_thigh_pitch" type="revolute">
    <origin rpy="0 0 0" xyz="-0.0  -0.1058 0.0"/>
    <parent link="link_rear_right_hip"/>
    <child link="link_rear_right_thigh"/>
    <axis xyz="0 1 0"/>
    <limit effort="45" lower="-3.14" upper="3.14" velocity="30"/>
  </joint>

  <link name="link_rear_right_calf">
    <inertial>
      <origin rpy="0 0 0" xyz="-0.0028 -0.0 -0.1278"/>
      <mass value="0.1353"/>
      <inertia ixx="1133339E-09" ixy="1e-09" ixz="4.9201e-05" iyy="1157176E-09" iyz="1e-08" izz="35874E-09"/>
    </inertial>
    <visual>
      <origin rpy="-1.57 0 0" xyz="0 0 0"/>
      <geometry>
        <mesh filename="../meshes/calf.STL"/>
      </geometry>
      <material name="">
        <color rgba="0.752941176470588 0.752941176470588 0.752941176470588 1"/>
      </material>
    </visual>
    <collision>
      <origin rpy="0 0 0" xyz="0 0 -0.138"/>
      <geometry>
        <box size="0.02 0.02 0.155"/>
      </geometry>
    </collision>
  </link>
  <joint name="joint_rear_right_calf_pitch" type="revolute">
    <origin rpy="0 0 0" xyz="0.0 0.0 -0.23"/>
    <parent link="link_rear_right_thigh"/>
    <child link="link_rear_right_calf"/>
    <axis xyz="0 1 0"/>
    <limit effort="45" lower="-3.14" upper="3.14" velocity="30"/>
  </joint>


  <link name="link_rear_right_foot">
    <inertial>
      <origin xyz="0 0 0" rpy="0 0 0" />
      <mass value="0.04" />
      <inertia ixx="9.6e-06" ixy="0" ixz="0" iyy="9.6e-06" iyz="0" izz="9.6e-06" />
    </inertial>
    <visual>
      <origin xyz="0 0 0" rpy="0 0 0" />
      <geometry>
        <sphere radius="0.02"/>
      </geometry>
    </visual>
    <collision>
      <origin rpy="0 0 0" xyz="0 0 0" />
      <geometry>
        <sphere radius="0.02" />
      </geometry>
    </collision>
  </link>
  <joint name="front_rear_right_joint" type="fixed" dont_collapse="true">
    <origin xyz="0 0 -0.23" rpy="0 0 0" />
    <parent link="link_rear_right_calf" />
    <child link="link_rear_right_foot" />
    <axis xyz="0 0 0" />
  </joint>

</robot>
